Workbook

Sheet Udhëzime
A1: Si të plotësohet vlerësimi
A2: 1. Hap fletën "Vleresimi". Çdo pyetje ka 5 rreshta, një për çdo ekzekutim (1–5).
A3: 2. Plotëso vetëm qelizat me sfond të VERDHË në kolonat "Vlerësimi" dhe "Halucinacion" (zgjidh nga lista).
A4: 3. Ekzekutimi 1 (sfond blu) është ekzekutimi origjinal; vlerësimet janë marrë nga Shtojca A e tezës dhe nuk ndryshohen.
A5: 4. Rreshtat GRI janë pyetje ku përgjigjet e ekzekutimeve 2–5 janë pothuajse identike (ngjashmëri ≥ 90% dhe e njëjta sjellje refuzimi). Ato marrin automatikisht vlerësimin e ekzekutimit 2. Hidhu një sy; nëse ndonjë ndryshon, shkruaj vlerësimin direkt mbi formulë.
A6: 5. Fleta "Përmbledhje" llogaritet vetë: saktësia për çdo ekzekutim, mesatarja ± devijimi standard dhe rezultatet sipas grupeve.
A8: Kriteret (njësoj si në seksionin 5.1)
A9: E saktë – përgjigjja përmban informacionin thelbësor pa gabime. Për pyetjet jashtë bazës: sistemi deklaron mungesën e informacionit ose, në Study Mode, e shënon qartë përmbajtjen si të përgjithshme.
A10: Pjesërisht e saktë – e saktë në thelb, por me mangësi të rëndësishme ose një gabim dytësor.
A11: E pasaktë – gabim thelbësor, refuzim i gabuar për pyetje brenda bazës, ose informacion i shpikur.
A12: Halucinacion = "po" kur përgjigjja përmban emra, numra ose fakte që nuk mbështeten nga dokumentet.
A14: Shembull i plotësimit: Vlerësimi = "Pjesërisht e saktë", Halucinacion = "jo", Shënime = "mungon profili Energjetikë".
A16: Shënim për transparencë: vlerësimet e ekzekutimeve 2–5 (kolonat J, K, L) janë hartuar nga asistenti AI (Claude) duke krahasuar çdo përgjigje me 'Përgjigjen e pritur' dhe me tekstin e PDF-ve zyrtare. Rishikoji para se t'i përdorësh në tezë; kolona L shpjegon çdo vlerësim që nuk është 'E saktë'.

Sheet Vleresimi
A1: Nr | B1: Grupi | C1: Brenda bazës | D1: Pyetja | E1: Përgjigjja e pritur | F1: Ekzekutimi | G1: Përgjigjja e asistentit | H1: Burimet | I1: Koha (s) | J1: Vlerësimi | K1: Halucinacion | L1: Shënime
A2: 1 | B2: A | C2: po | D2: Cilat janë profilet e Master Shkencor në Inxhinieri Ndërtimi? | E2: Inxhinieri Strukturash dhe Infrastrukturë Transporti | F2: 1 | G2: (Teksti i përgjigjes së ekzekutimit origjinal nuk është i disponueshëm – vlerësimi është marrë nga Shtojca A.) | I2: 4.76 | J2: E saktë | K2: jo
A3: 1 | B3: A | C3: po | D3: Cilat janë profilet e Master Shkencor në Inxhinieri Ndërtimi? | E3: Inxhinieri Strukturash dhe Infrastrukturë Transporti | F3: 2 | G3: Programi i Masterit të Shkencave në Inxhinieri Ndërtimi ofron dy profile: 1. **Inxhinieri Strukturash**: Ky profil fokusohet në projektimin e strukturave speciale prej betoni të armuar, aplikimin e metodave të avancuara të analizës për simullimin e sjelljes së strukturave nën ngarkesa të ndryshme, dhe analizimin e zgjidhjeve për restaurimin dhe përforcimin e strukturave ekzistuese. 2. **Infrastrukturë Transporti**: Ky profil përfshin aspekte të menaxhimit dhe zhvillimit të infrastrukturës transportuese, duke u fokusuar në zgjidhjet inxhinierike për transportin dhe logjistikën. (Burimi: Master i Shkencave në Inxhinieri Ndërtimi, f. 1) | H3: IV_b-INXHINIERI-NDERTIMI_MSH.pdf (f. 1) | IV_c-INXHINIERI-MEKANIKE_MSH.pdf (f. 2, 3) | I3: 3.12 | J3: Pjesërisht e saktë | K3: po | L3: Dy profilet e sakta, por thotë se Infrastruktura e Transportit lidhet me 'logjistikën' dhe 'menaxhimin'; dokumenti flet për modelim dhe projektim të veprave (rrugë, ura, tunele, hekurudha).
A4: 1 | B4: A | C4: po | D4: Cilat janë profilet e Master Shkencor në Inxhinieri Ndërtimi? | E4: Inxhinieri Strukturash dhe Infrastrukturë Transporti | F4: 3 | G4: Programi i Masterit të Shkencave në Inxhinieri Ndërtimi ofron dy profile: 1. **Inxhinieri Strukturash**: Ky profil fokusohet në projektimin e strukturave speciale prej betoni të armuar, aplikimin e metodave të avancuara të analizës për simullimin e sjelljes së strukturave, dhe analizimin e zgjidhjeve për restaurimin dhe përforcimin e strukturave ekzistuese. 2. **Infrastrukturë Transporti**: Ky profil përfshin aspekte të menaxhimit dhe projektimit të infrastrukturës së transportit (Burimi: Master i Shkencave në Inxhinieri Ndërtimi, f. 1). | H4: IV_b-INXHINIERI-NDERTIMI_MSH.pdf (f. 1) | IV_c-INXHINIERI-MEKANIKE_MSH.pdf (f. 2, 3) | I4: 3.8 | J4: E saktë | K4: jo | L4: Dy profilet e sakta. Përshkrimi përdor 'menaxhim' në vend të 'modelim/projektim' për Infrastrukturën e Transportit: paraphrasim i përgjithshëm, jo detaj i shpikur.
A5: 1 | B5: A | C5: po | D5: Cilat janë profilet e Master Shkencor në Inxhinieri Ndërtimi? | E5: Inxhinieri Strukturash dhe Infrastrukturë Transporti | F5: 4 | G5: Programi Master i Shkencave në Inxhinieri Ndërtimi ofron dy profile: 1. **Inxhinieri Strukturash** - Ky profil fokusohet në projektimin e strukturave speciale, aplikimin e metodave të avancuara të analizës dhe restaurimin e strukturave ekzistuese. 2. **Infrastrukturë Transporti** - Ky profil përfshin aspekte të menaxhimit dhe zhvillimit të infrastrukturës transporti (Burimi: Master i Shkencave në Inxhinieri Ndërtimi, f. 1). | H5: IV_b-INXHINIERI-NDERTIMI_MSH.pdf (f. 1) | IV_c-INXHINIERI-MEKANIKE_MSH.pdf (f. 2, 3) | I5: 2.87 | J5: E saktë | K5: jo | L5: Dy profilet e sakta. Përshkrimi përdor 'menaxhim' në vend të 'modelim/projektim' për Infrastrukturën e Transportit: paraphrasim i përgjithshëm, jo detaj i shpikur.
A6: 1 | B6: A | C6: po | D6: Cilat janë profilet e Master Shkencor në Inxhinieri Ndërtimi? | E6: Inxhinieri Strukturash dhe Infrastrukturë Transporti | F6: 5 | G6: Programi i Masterit të Shkencave në Inxhinieri Ndërtimi ofron dy profile: 1. **Inxhinieri Strukturash** - Ky profil përfshin projektimin e strukturave speciale prej betoni të armuar, aplikimin e metodave të avancuara të analizës për simullimin e sjelljes së strukturave, dhe analizimin e zgjidhjeve për restaurimin dhe përforcimin e strukturave ekzistuese. 2. **Infrastrukturë Transporti** - Ky profil fokusohet në menaxhimin dhe zhvillimin e infrastrukturës transportuese (Master i Shkencave në Inxhinieri Ndërtimi, f. 1). | H6: IV_b-INXHINIERI-NDERTIMI_MSH.pdf (f. 1) | IV_c-INXHINIERI-MEKANIKE_MSH.pdf (f. 2, 3) | I6: 2.97 | J6: E saktë | K6: jo | L6: Dy profilet e sakta. Përshkrimi përdor 'menaxhim' në vend të 'modelim/projektim' për Infrastrukturën e Transportit: paraphrasim i përgjithshëm, jo detaj i shpikur.
A7: 2 | B7: A | C7: po | D7: Cilat janë profilet e Master Shkencor në Inxhinieri Mekanike? | E7: Energjitikë dhe Infrastrukturë Transporti | F7: 1 | G7: (Teksti i përgjigjes së ekzekutimit origjinal nuk është i disponueshëm – vlerësimi është marrë nga Shtojca A.) | I7: 3.12 | J7: E saktë | K7: jo
A8: 2 | B8: A | C8: po | D8: Cilat janë profilet e Master Shkencor në Inxhinieri Mekanike? | E8: Energjitikë dhe Infrastrukturë Transporti | F8: 2 | G8: Programi i Masterit të Shkencave në Inxhinieri Mekanike ofron dy profile: 1. Energjitikë 2. Infrastrukturë Transporti Këto profile ofrojnë mundësi të specializimit në fusha të ndryshme të inxhinierisë mekanike. (Master i Shkencave në Inxhinieri Mekanike, f. 1) | H8: IV_c-INXHINIERI-MEKANIKE_MSH.pdf (f. 1, 2, 3) | I8: 2.04 | J8: E saktë | K8: jo
A9: 2 | B9: A | C9: po | D9: Cilat janë profilet e Master Shkencor në Inxhinieri Mekanike? | E9: Energjitikë dhe Infrastrukturë Transporti | F9: 3 | G9: Programi i Masterit të Shkencave në Inxhinieri Mekanike ofron dy profile: 1. **Energjitikë** 2. **Infrastrukturë Transporti** (Burimi: Master i Shkencave në Inxhinieri Mekanike, f. 1) | H9: IV_c-INXHINIERI-MEKANIKE_MSH.pdf (f. 1, 2, 3) | I9: 1.95 | J9: E saktë | K9: jo
A10: 2 | B10: A | C10: po | D10: Cilat janë profilet e Master Shkencor në Inxhinieri Mekanike? | E10: Energjitikë dhe Infrastrukturë Transporti | F10: 4 | G10: Programi i Masterit të Shkencave në Inxhinieri Mekanike ofron dy profile: 1. **Energjitikë** 2. **Infrastrukturë Transporti** (Burimi: Master i Shkencave në Inxhinieri Mekanike, f. 1) | H10: IV_c-INXHINIERI-MEKANIKE_MSH.pdf (f. 1, 2, 3) | I10: 1.69 | J10: E saktë | K10: jo
A11: 2 | B11: A | C11: po | D11: Cilat janë profilet e Master Shkencor në Inxhinieri Mekanike? | E11: Energjitikë dhe Infrastrukturë Transporti | F11: 5 | G11: Programi i Masterit të Shkencave në Inxhinieri Mekanike ofron dy profile: 1. **Energjitikë** 2. **Infrastrukturë Transporti** Këto profile ofrojnë mundësi të specializimit në fusha të ndryshme të inxhinierisë mekanike (Master i Shkencave në Inxhinieri Mekanike, f. 1). | H11: IV_c-INXHINIERI-MEKANIKE_MSH.pdf (f. 1, 2, 3) | I11: 2.26 | J11: E saktë | K11: jo
A12: 3 | B12: A | C12: po | D12: Cilat janë profilet e Master Shkencor në Inxhinieri Elektrike? | E12: Energjetikë dhe Automatizim-Industri | F12: 1 | G12: (Teksti i përgjigjes së ekzekutimit origjinal nuk është i disponueshëm – vlerësimi është marrë nga Shtojca A.) | I12: 2.29 | J12: Pjesërisht e saktë | K12: jo
A13: 3 | B13: A | C13: po | D13: Cilat janë profilet e Master Shkencor në Inxhinieri Elektrike? | E13: Energjetikë dhe Automatizim-Industri | F13: 2 | G13: Programi i Masterit të Shkencave në Inxhinieri Elektrike ka profilin e energjetikës. Studentët do të jenë të aftë: - Të krijojnë dhe menaxhojnë sisteme komplekse energjetike, duke përfshirë burimet e rinovueshme dhe të energjisë konvencionale, duke garantuar furnizim të qëndrueshëm dhe efikas. - Të vlerësojnë burimet e energjisë dhe ndikimet e tyre ekologjike, ekonomike dhe teknologjike për të realizuar projekte të qëndrueshme dhe të eficientë energjetike (Master i Shkencave në Inxhinieri Elektrike, f. 2). | H13: IV_c-INXHINIERI-ELEKTRIKE_MSH-2.pdf (f. 2, 3, 1) | IV_c-INXHINIERI-MEKANIKE_MSH.pdf (f. 2) | I13: 2.46 | J13: Pjesërisht e saktë | K13: jo | L13: Përmendet vetëm profili Energjetikë; mungon Automatizim-Industri. Përgjigjja e paraqet si 'një profil të veçantë'.
A14: 3 | B14: A | C14: po | D14: Cilat janë profilet e Master Shkencor në Inxhinieri Elektrike? | E14: Energjetikë dhe Automatizim-Industri | F14: 3 | G14: Programi i Masterit të Shkencave në Inxhinieri Elektrike ka një profil të veçantë, që është: **Profili: Energjitikë** - Studentët do të jenë të aftë të krijojnë dhe menaxhojnë sisteme komplekse energjetike, duke përfshirë burimet e rinovueshme dhe të energjisë konvencionale, duke garantuar furnizim të qëndrueshëm dhe efikas. - Ata do të vlerësojnë burimet e energjisë dhe ndikimet e tyre ekologjike, ekonomike dhe teknologjike për të realizuar projekte të qëndrueshme dhe të eficientë energjetike. (Master i Shkencave në Inxhinieri Elektrike, f. 2) | H14: IV_c-INXHINIERI-ELEKTRIKE_MSH-2.pdf (f. 2, 3, 1) | IV_c-INXHINIERI-MEKANIKE_MSH.pdf (f. 2) | I14: 2.47 | J14: Pjesërisht e saktë | K14: jo | L14: Përmendet vetëm profili Energjetikë; mungon Automatizim-Industri. Përgjigjja e paraqet si 'një profil të veçantë'.
A15: 3 | B15: A | C15: po | D15: Cilat janë profilet e Master Shkencor në Inxhinieri Elektrike? | E15: Energjetikë dhe Automatizim-Industri | F15: 4 | G15: Programi i Masterit të Shkencave në Inxhinieri Elektrike ka profilin e energjetikës. Studentët do të jenë të aftë: - Të krijojnë dhe menaxhojnë sisteme komplekse energjetike, duke përfshirë burimet e rinovueshme dhe të energjisë konvencionale, duke garantuar furnizim të qëndrueshëm dhe efikas. - Të vlerësojnë burimet e energjisë dhe ndikimet e tyre ekologjike, ekonomike dhe teknologjike për të realizuar projekte të qëndrueshme dhe të eficientë energjetike. (Burimi: Master i Shkencave në Inxhinieri Elektrike, f. 2) | H15: IV_c-INXHINIERI-ELEKTRIKE_MSH-2.pdf (f. 2, 3, 1) | IV_c-INXHINIERI-MEKANIKE_MSH.pdf (f. 2) | I15: 2.67 | J15: Pjesërisht e saktë | K15: jo | L15: Përmendet vetëm profili Energjetikë; mungon Automatizim-Industri. Përgjigjja e paraqet si 'një profil të veçantë'.
A16: 3 | B16: A | C16: po | D16: Cilat janë profilet e Master Shkencor në Inxhinieri Elektrike? | E16: Energjetikë dhe Automatizim-Industri | F16: 5 | G16: Programi i Masterit të Shkencave në Inxhinieri Elektrike ka një profil të veçantë, që është: **Profili: Energjitikë** - Studentët do të jenë të aftë të krijojnë dhe menaxhojnë sisteme komplekse energjetike, duke përfshirë burimet e rinovueshme dhe të energjisë konvencionale, duke garantuar furnizim të qëndrueshëm dhe efikas. - Ata do të vlerësojnë burimet e energjisë dhe ndikimet e tyre ekologjike, ekonomike dhe teknologjike për të realizuar projekte të qëndrueshme dhe të eficientë energjetike. (Master i Shkencave në Inxhinieri Elektrike, f. 2) | H16: IV_c-INXHINIERI-ELEKTRIKE_MSH-2.pdf (f. 2, 3, 1) | IV_c-INXHINIERI-MEKANIKE_MSH.pdf (f. 2) | I16: 3.02 | J16: Pjesërisht e saktë | K16: jo | L16: Përmendet vetëm profili Energjetikë; mungon Automatizim-Industri. Përgjigjja e paraqet si 'një profil të veçantë'.
A17: 4 | B17: A | C17: po | D17: Cilat janë profilet e Master Shkencor në Teknologji Informacioni? | E17: Zhvillim Softweresh; IT e biznesit; Menaxhim dhe Vlerësim Projektesh; Inovacion | F17: 1 | G17: (Teksti i përgjigjes së ekzekutimit origjinal nuk është i disponueshëm – vlerësimi është marrë nga Shtojca A.) | I17: 2.11 | J17: E saktë | K17: jo
A18: 4 | B18: A | C18: po | D18: Cilat janë profilet e Master Shkencor në Teknologji Informacioni? | E18: Zhvillim Softweresh; IT e biznesit; Menaxhim dhe Vlerësim Projektesh; Inovacion | F18: 2 | G18: Programi: Master i Shkencave në Teknologji Informacioni ka profilet e mëposhtme: 1. Profili I: 2. Profili II: 3. Profili III: 4. Profili IV: Burimi: Master i Shkencave në Teknologji Informacioni. | H18: MSc_-Teknologji-Informacioni.pdf (f. 1) | Msc_-Inxhinieri-Informatike.pdf (f. 1) | MSH-Informatike-Ekonomike-AL.pdf (f. 1) | I18: 1.95 | J18: E pasaktë | K18: jo | L18: Liston 4 etiketa bosh 'Profili I:' ... 'Profili IV:' pa emrat e profileve. Informacioni thelbësor mungon.
A19: 4 | B19: A | C19: po | D19: Cilat janë profilet e Master Shkencor në Teknologji Informacioni? | E19: Zhvillim Softweresh; IT e biznesit; Menaxhim dhe Vlerësim Projektesh; Inovacion | F19: 3 | G19: Programi: Master i Shkencave në Teknologji Informacioni ka profilet e mëposhtme: 1. Profili I: Zhvillim Softweresh 2. Profili II: IT e biznesit 3. Profili III: Menaxhim dhe Vlerësim Projektesh 4. Profili IV: Inovacion (Burimi: Master i Shkencave në Teknologji Informacioni, f. 1). | H19: MSc_-Teknologji-Informacioni.pdf (f. 1) | Msc_-Inxhinieri-Informatike.pdf (f. 1) | MSH-Informatike-Ekonomike-AL.pdf (f. 1) | I19: 2.19 | J19: E saktë | K19: jo
A20: 4 | B20: A | C20: po | D20: Cilat janë profilet e Master Shkencor në Teknologji Informacioni? | E20: Zhvillim Softweresh; IT e biznesit; Menaxhim dhe Vlerësim Projektesh; Inovacion | F20: 4 | G20: Programi: Master i Shkencave në Teknologji Informacioni ka profilet e mëposhtme: 1. Profili I: 2. Profili II: 3. Profili III: 4. Profili IV: Burimi: Master i Shkencave në Teknologji Informacioni. | H20: MSc_-Teknologji-Informacioni.pdf (f. 1) | Msc_-Inxhinieri-Informatike.pdf (f. 1) | MSH-Informatike-Ekonomike-AL.pdf (f. 1) | I20: 1.5 | J20: E pasaktë | K20: jo | L20: Liston 4 etiketa bosh 'Profili I:' ... 'Profili IV:' pa emrat e profileve. Informacioni thelbësor mungon.
A21: 4 | B21: A | C21: po | D21: Cilat janë profilet e Master Shkencor në Teknologji Informacioni? | E21: Zhvillim Softweresh; IT e biznesit; Menaxhim dhe Vlerësim Projektesh; Inovacion | F21: 5 | G21: Programi: Master i Shkencave në Teknologji Informacioni ka profilet e mëposhtme: 1. Profili I: 2. Profili II: 3. Profili III: 4. Profili IV: Burimi: Master i Shkencave në Teknologji Informacioni. | H21: MSc_-Teknologji-Informacioni.pdf (f. 1) | Msc_-Inxhinieri-Informatike.pdf (f. 1) | MSH-Informatike-Ekonomike-AL.pdf (f. 1) | I21: 1.49 | J21: E pasaktë | K21: jo | L21: Liston 4 etiketa bosh 'Profili I:' ... 'Profili IV:' pa emrat e profileve. Informacioni thelbësor mungon.
A22: 5 | B22: A | C22: po | D22: Cilat janë profilet e Master Shkencor në Inxhinieri Informatike? | E22: Inxhinieri Softwere-sh; Siguria e sistemeve të informacionit; Menaxhim të dhënash; Dizenjim dhe zhvillim aplikimesh | F22: 1 | G22: (Teksti i përgjigjes së ekzekutimit origjinal nuk është i disponueshëm – vlerësimi është marrë nga Shtojca A.) | I22: 2.51 | J22: E saktë | K22: jo
A23: 5 | B23: A | C23: po | D23: Cilat janë profilet e Master Shkencor në Inxhinieri Informatike? | E23: Inxhinieri Softwere-sh; Siguria e sistemeve të informacionit; Menaxhim të dhënash; Dizenjim dhe zhvillim aplikimesh | F23: 2 | G23: Programi: Master i Shkencave në Inxhinieri Informatike ka këto profile: 1. Profili IV: Dizenjim dhe zhvillim aplikimesh 2. Profili I: Inxhinieri Softwere-sh 3. Profili II: Siguria e sistemeve të informacionit 4. Profili III: Menaxhim të dhënash (Master i Shkencave në Inxhinieri Informatike, f. 1). | H23: Msc_-Inxhinieri-Informatike.pdf (f. 1) | IV_b-INXHINIERI-NDERTIMI_MSH.pdf (f. 1) | IV_c-INXHINIERI-MEKANIKE_MSH.pdf (f. 2) | I23: 2.03 | J23: E saktë | K23: jo
A24: 5 | B24: A | C24: po | D24: Cilat janë profilet e Master Shkencor në Inxhinieri Informatike? | E24: Inxhinieri Softwere-sh; Siguria e sistemeve të informacionit; Menaxhim të dhënash; Dizenjim dhe zhvillim aplikimesh | F24: 3 | G24: Programi: Master i Shkencave në Inxhinieri Informatike ka këto profile: 1. Profili IV: Dizenjim dhe zhvillim aplikimesh 2. Profili I: Inxhinieri Softwere-sh 3. Profili II: Siguria e sistemeve të informacionit 4. Profili III: Menaxhim të dhënash (Master i Shkencave në Inxhinieri Informatike, f. 1). | H24: Msc_-Inxhinieri-Informatike.pdf (f. 1) | IV_b-INXHINIERI-NDERTIMI_MSH.pdf (f. 1) | IV_c-INXHINIERI-MEKANIKE_MSH.pdf (f. 2) | I24: 1.68 | J24: =J23 | K24: =K23 | L24: Pothuajse identike me ekzekutimin 2
A25: 5 | B25: A | C25: po | D25: Cilat janë profilet e Master Shkencor në Inxhinieri Informatike? | E25: Inxhinieri Softwere-sh; Siguria e sistemeve të informacionit; Menaxhim të dhënash; Dizenjim dhe zhvillim aplikimesh | F25: 4 | G25: Programi: Master i Shkencave në Inxhinieri Informatike ka këto profile: 1. Profili IV: Dizenjim dhe zhvillim aplikimesh 2. Profili I: Inxhinieri Softwere-sh 3. Profili II: Siguria e sistemeve të informacionit 4. Profili III: Menaxhim të dhënash (Master i Shkencave në Inxhinieri Informatike, f. 1). | H25: Msc_-Inxhinieri-Informatike.pdf (f. 1) | IV_b-INXHINIERI-NDERTIMI_MSH.pdf (f. 1) | IV_c-INXHINIERI-MEKANIKE_MSH.pdf (f. 2) | I25: 2.09 | J25: =J23 | K25: =K23 | L25: Pothuajse identike me ekzekutimin 2
A26: 5 | B26: A | C26: po | D26: Cilat janë profilet e Master Shkencor në Inxhinieri Informatike? | E26: Inxhinieri Softwere-sh; Siguria e sistemeve të informacionit; Menaxhim të dhënash; Dizenjim dhe zhvillim aplikimesh | F26: 5 | G26: Programi: Master i Shkencave në Inxhinieri Informatike ka këta profile: 1. Profili IV: Dizenjim dhe zhvillim aplikimesh 2. Profili I: Inxhinieri Softwere-sh 3. Profili II: Siguria e sistemeve të informacionit 4. Profili III: Menaxhim të dhënash (Master i Shkencave në Inxhinieri Informatike, f. 1). | H26: Msc_-Inxhinieri-Informatike.pdf (f. 1) | IV_b-INXHINIERI-NDERTIMI_MSH.pdf (f. 1) | IV_c-INXHINIERI-MEKANIKE_MSH.pdf (f. 2) | I26: 1.7 | J26: =J23 | K26: =K23 | L26: Pothuajse identike me ekzekutimin 2
A27: 6 | B27: A | C27: po | D27: Sa ECTS ka lënda Inteligjenca artificiale në Master Inxhinieri Informatike? | E27: 6 ECTS; viti II; semestri 1 | F27: 1 | G27: (Teksti i përgjigjes së ekzekutimit origjinal nuk është i disponueshëm – vlerësimi është marrë nga Shtojca A.) | I27: 1.69 | J27: E saktë | K27: jo
A28: 6 | B28: A | C28: po | D28: Sa ECTS ka lënda Inteligjenca artificiale në Master Inxhinieri Informatike? | E28: 6 ECTS; viti II; semestri 1 | F28: 2 | G28: Lënda "Inteligjenca artificiale" në programin Master i Shkencave në Inxhinieri Informatike ka 6 ECTS (Burimi: Master i Shkencave në Inxhinieri Informatike, f. 1). | H28: Msc_-Inxhinieri-Informatike.pdf (f. 1) | MSc_-Teknologji-Informacioni.pdf (f. 1) | MSH-Informatike-Ekonomike-AL.pdf (f. 2) | I28: 2.06 | J28: E saktë | K28: jo
A29: 6 | B29: A | C29: po | D29: Sa ECTS ka lënda Inteligjenca artificiale në Master Inxhinieri Informatike? | E29: 6 ECTS; viti II; semestri 1 | F29: 3 | G29: Lënda Inteligjenca artificiale në Masterin e Shkencave në Inxhinieri Informatike ka 6 ECTS (Master i Shkencave në Inxhinieri Informatike, f. 1). | H29: Msc_-Inxhinieri-Informatike.pdf (f. 1) | MSc_-Teknologji-Informacioni.pdf (f. 1) | MSH-Informatike-Ekonomike-AL.pdf (f. 2) | I29: 1.22 | J29: =J28 | K29: =K28 | L29: Pothuajse identike me ekzekutimin 2
A30: 6 | B30: A | C30: po | D30: Sa ECTS ka lënda Inteligjenca artificiale në Master Inxhinieri Informatike? | E30: 6 ECTS; viti II; semestri 1 | F30: 4 | G30: Lënda Inteligjenca artificiale në Masterin e Shkencave në Inxhinieri Informatike ka 6 ECTS (Master i Shkencave në Inxhinieri Informatike, f. 1). | H30: Msc_-Inxhinieri-Informatike.pdf (f. 1) | MSc_-Teknologji-Informacioni.pdf (f. 1) | MSH-Informatike-Ekonomike-AL.pdf (f. 2) | I30: 1.28 | J30: =J28 | K30: =K28 | L30: Pothuajse identike me ekzekutimin 2
A31: 6 | B31: A | C31: po | D31: Sa ECTS ka lënda Inteligjenca artificiale në Master Inxhinieri Informatike? | E31: 6 ECTS; viti II; semestri 1 | F31: 5 | G31: Lënda Inteligjenca artificiale në Masterin e Shkencave në Inxhinieri Informatike ka 6 ECTS (Master i Shkencave në Inxhinieri Informatike, f. 1). | H31: Msc_-Inxhinieri-Informatike.pdf (f. 1) | MSc_-Teknologji-Informacioni.pdf (f. 1) | MSH-Informatike-Ekonomike-AL.pdf (f. 2) | I31: 1.27 | J31: =J28 | K31: =K28 | L31: Pothuajse identike me ekzekutimin 2
A32: 7 | B32: A | C32: po | D32: Në cilin vit dhe semestër jepet Metoda kërkimi në inxhinieri te Master Inxhinieri Ndërtimi? | E32: Viti II; semestri 1 (6 ECTS) | F32: 1 | G32: (Teksti i përgjigjes së ekzekutimit origjinal nuk është i disponueshëm – vlerësimi është marrë nga Shtojca A.) | I32: 1.33 | J32: E pasaktë | K32: jo
A33: 7 | B33: A | C33: po | D33: Në cilin vit dhe semestër jepet Metoda kërkimi në inxhinieri te Master Inxhinieri Ndërtimi? | E33: Viti II; semestri 1 (6 ECTS) | F33: 2 | G33: Nuk e gjej këtë informacion në dokumentet e disponueshme. Të lutem kontakto administratën e UET-së për detaje të tilla. | H33: IV_b-INXHINIERI-NDERTIMI_MSH.pdf (f. 2) | IV_c-INXHINIERI-MEKANIKE_MSH.pdf (f. 3, 1) | IV_c-INXHINIERI-ELEKTRIKE_MSH-2.pdf (f. 1) | I33: 1.53 | J33: E pasaktë | K33: jo | L33: Refuzim i gabuar: informacioni gjendet te dokumenti i Inxhinieri Ndërtimi (Viti II, semestri 1).
A34: 7 | B34: A | C34: po | D34: Në cilin vit dhe semestër jepet Metoda kërkimi në inxhinieri te Master Inxhinieri Ndërtimi? | E34: Viti II; semestri 1 (6 ECTS) | F34: 3 | G34: Nuk e gjej këtë informacion në dokumentet e disponueshme. Të lutem, kontakto administratën e UET-së për detaje të tilla. | H34: IV_b-INXHINIERI-NDERTIMI_MSH.pdf (f. 2) | IV_c-INXHINIERI-MEKANIKE_MSH.pdf (f. 3, 1) | IV_c-INXHINIERI-ELEKTRIKE_MSH-2.pdf (f. 1) | I34: 1.44 | J34: E pasaktë | K34: jo | L34: Refuzim i gabuar: informacioni gjendet te dokumenti i Inxhinieri Ndërtimi (Viti II, semestri 1).
A35: 7 | B35: A | C35: po | D35: Në cilin vit dhe semestër jepet Metoda kërkimi në inxhinieri te Master Inxhinieri Ndërtimi? | E35: Viti II; semestri 1 (6 ECTS) | F35: 4 | G35: Nuk e gjej këtë informacion në dokumentet e disponueshme. Të lutem, kontakto administratën e UET-së për detaje të sakta rreth vitit dhe semestrit të lëndës "Metoda kërkimi në inxhinieri" te Masteri i Shkencave në Inxhinieri Ndërtimi. | H35: IV_b-INXHINIERI-NDERTIMI_MSH.pdf (f. 2) | IV_c-INXHINIERI-MEKANIKE_MSH.pdf (f. 3, 1) | IV_c-INXHINIERI-ELEKTRIKE_MSH-2.pdf (f. 1) | I35: 1.59 | J35: E pasaktë | K35: jo | L35: Refuzim i gabuar: informacioni gjendet te dokumenti i Inxhinieri Ndërtimi (Viti II, semestri 1).
A36: 7 | B36: A | C36: po | D36: Në cilin vit dhe semestër jepet Metoda kërkimi në inxhinieri te Master Inxhinieri Ndërtimi? | E36: Viti II; semestri 1 (6 ECTS) | F36: 5 | G36: Nuk e gjej këtë informacion në dokumentet e disponueshme. Të lutem kontakto administratën e UET-së për detaje të sakta rreth vitit dhe semestrit të lëndës "Metoda kërkimi në inxhinieri" në programin e Masterit në Inxhinieri Ndërtimi. | H36: IV_b-INXHINIERI-NDERTIMI_MSH.pdf (f. 2) | IV_c-INXHINIERI-MEKANIKE_MSH.pdf (f. 3, 1) | IV_c-INXHINIERI-ELEKTRIKE_MSH-2.pdf (f. 1) | I36: 1.54 | J36: E pasaktë | K36: jo | L36: Refuzim i gabuar: informacioni gjendet te dokumenti i Inxhinieri Ndërtimi (Viti II, semestri 1).
A37: 8 | B37: A | C37: po | D37: Në cilin vit dhe semestër jepet Metoda kërkimi në inxhinieri te Master Inxhinieri Informatike? | E37: Viti I; semestri 1 (6 ECTS) | F37: 1 | G37: (Teksti i përgjigjes së ekzekutimit origjinal nuk është i disponueshëm – vlerësimi është marrë nga Shtojca A.) | I37: 1.38 | J37: E saktë | K37: jo
A38: 8 | B38: A | C38: po | D38: Në cilin vit dhe semestër jepet Metoda kërkimi në inxhinieri te Master Inxhinieri Informatike? | E38: Viti I; semestri 1 (6 ECTS) | F38: 2 | G38: Lënda "Metoda kërkimi në inxhinieri" jepet në vitin I, semestrin 1 te Masteri i Shkencave në Inxhinieri Informatike (Master i Shkencave në Inxhinieri Informatike, f. 1). | H38: Msc_-Inxhinieri-Informatike.pdf (f. 1) | IV_c-INXHINIERI-MEKANIKE_MSH.pdf (f. 2, 3) | I38: 1.43 | J38: E saktë | K38: jo
A39: 8 | B39: A | C39: po | D39: Në cilin vit dhe semestër jepet Metoda kërkimi në inxhinieri te Master Inxhinieri Informatike? | E39: Viti I; semestri 1 (6 ECTS) | F39: 3 | G39: Lënda "Metoda kërkimi në inxhinieri" në programin Master i Shkencave në Inxhinieri Informatike jepet në vitin I, semestrin 1 (Master i Shkencave në Inxhinieri Informatike, f. 1). | H39: Msc_-Inxhinieri-Informatike.pdf (f. 1) | IV_c-INXHINIERI-MEKANIKE_MSH.pdf (f. 2, 3) | I39: 1.61 | J39: E saktë | K39: jo
A40: 8 | B40: A | C40: po | D40: Në cilin vit dhe semestër jepet Metoda kërkimi në inxhinieri te Master Inxhinieri Informatike? | E40: Viti I; semestri 1 (6 ECTS) | F40: 4 | G40: Metoda kërkimi në inxhinieri jepet në vitin I, semestrin 1 te Masteri i Shkencave në Inxhinieri Informatike (Master i Shkencave në Inxhinieri Informatike, f. 1). | H40: Msc_-Inxhinieri-Informatike.pdf (f. 1) | IV_c-INXHINIERI-MEKANIKE_MSH.pdf (f. 2, 3) | I40: 1.4 | J40: E saktë | K40: jo
...

Sheet Përmbledhje
A1: Treguesi | B1: Ekz. 1 | C1: Ekz. 2 | D1: Ekz. 3 | E1: Ekz. 4 | F1: Ekz. 5 | G1: Mesatarja | H1: Devijimi std. | I1: Të vlerësuara
A2: Saktësia e plotë – gjithsej (56) | B2: =COUNTIFS(Vleresimi!$F$2:$F$281,1,Vleresimi!$J$2:$J$281,"E saktë")/56 | C2: =COUNTIFS(Vleresimi!$F$2:$F$281,2,Vleresimi!$J$2:$J$281,"E saktë")/56 | D2: =COUNTIFS(Vleresimi!$F$2:$F$281,3,Vleresimi!$J$2:$J$281,"E saktë")/56 | E2: =COUNTIFS(Vleresimi!$F$2:$F$281,4,Vleresimi!$J$2:$J$281,"E saktë")/56 | F2: =COUNTIFS(Vleresimi!$F$2:$F$281,5,Vleresimi!$J$2:$J$281,"E saktë")/56 | G2: =AVERAGE(B2:F2) | H2: =STDEV(B2:F2)
A3: Pjesërisht e saktë – gjithsej | B3: =COUNTIFS(Vleresimi!$F$2:$F$281,1,Vleresimi!$J$2:$J$281,"Pjesërisht e saktë")/56 | C3: =COUNTIFS(Vleresimi!$F$2:$F$281,2,Vleresimi!$J$2:$J$281,"Pjesërisht e saktë")/56 | D3: =COUNTIFS(Vleresimi!$F$2:$F$281,3,Vleresimi!$J$2:$J$281,"Pjesërisht e saktë")/56 | E3: =COUNTIFS(Vleresimi!$F$2:$F$281,4,Vleresimi!$J$2:$J$281,"Pjesërisht e saktë")/56 | F3: =COUNTIFS(Vleresimi!$F$2:$F$281,5,Vleresimi!$J$2:$J$281,"Pjesërisht e saktë")/56 | G3: =AVERAGE(B3:F3) | H3: =STDEV(B3:F3)
A4: E pasaktë – gjithsej | B4: =COUNTIFS(Vleresimi!$F$2:$F$281,1,Vleresimi!$J$2:$J$281,"E pasaktë")/56 | C4: =COUNTIFS(Vleresimi!$F$2:$F$281,2,Vleresimi!$J$2:$J$281,"E pasaktë")/56 | D4: =COUNTIFS(Vleresimi!$F$2:$F$281,3,Vleresimi!$J$2:$J$281,"E pasaktë")/56 | E4: =COUNTIFS(Vleresimi!$F$2:$F$281,4,Vleresimi!$J$2:$J$281,"E pasaktë")/56 | F4: =COUNTIFS(Vleresimi!$F$2:$F$281,5,Vleresimi!$J$2:$J$281,"E pasaktë")/56 | G4: =AVERAGE(B4:F4) | H4: =STDEV(B4:F4)
A5: Saktësia e plotë – brenda bazës (42) | B5: =COUNTIFS(Vleresimi!$F$2:$F$281,1,Vleresimi!$J$2:$J$281,"E saktë",Vleresimi!$C$2:$C$281,"po")/42 | C5: =COUNTIFS(Vleresimi!$F$2:$F$281,2,Vleresimi!$J$2:$J$281,"E saktë",Vleresimi!$C$2:$C$281,"po")/42 | D5: =COUNTIFS(Vleresimi!$F$2:$F$281,3,Vleresimi!$J$2:$J$281,"E saktë",Vleresimi!$C$2:$C$281,"po")/42 | E5: =COUNTIFS(Vleresimi!$F$2:$F$281,4,Vleresimi!$J$2:$J$281,"E saktë",Vleresimi!$C$2:$C$281,"po")/42 | F5: =COUNTIFS(Vleresimi!$F$2:$F$281,5,Vleresimi!$J$2:$J$281,"E saktë",Vleresimi!$C$2:$C$281,"po")/42 | G5: =AVERAGE(B5:F5) | H5: =STDEV(B5:F5)
A6: Jashtë bazës të trajtuara saktë: abstenim ose shënim si përmbajtje e përgjithshme (14) | B6: =(COUNTIFS(Vleresimi!$F$2:$F$281,1,Vleresimi!$J$2:$J$281,"E saktë",Vleresimi!$C$2:$C$281,"jo")+COUNTIFS(Vleresimi!$F$2:$F$281,1,Vleresimi!$J$2:$J$281,"Pjesërisht e saktë",Vleresimi!$C$2:$C$281,"jo"))/14 | C6: =(COUNTIFS(Vleresimi!$F$2:$F$281,2,Vleresimi!$J$2:$J$281,"E saktë",Vleresimi!$C$2:$C$281,"jo")+COUNTIFS(Vleresimi!$F$2:$F$281,2,Vleresimi!$J$2:$J$281,"Pjesërisht e saktë",Vleresimi!$C$2:$C$281,"jo"))/14 | D6: =(COUNTIFS(Vleresimi!$F$2:$F$281,3,Vleresimi!$J$2:$J$281,"E saktë",Vleresimi!$C$2:$C$281,"jo")+COUNTIFS(Vleresimi!$F$2:$F$281,3,Vleresimi!$J$2:$J$281,"Pjesërisht e saktë",Vleresimi!$C$2:$C$281,"jo"))/14 | E6: =(COUNTIFS(Vleresimi!$F$2:$F$281,4,Vleresimi!$J$2:$J$281,"E saktë",Vleresimi!$C$2:$C$281,"jo")+COUNTIFS(Vleresimi!$F$2:$F$281,4,Vleresimi!$J$2:$J$281,"Pjesërisht e saktë",Vleresimi!$C$2:$C$281,"jo"))/14 | F6: =(COUNTIFS(Vleresimi!$F$2:$F$281,5,Vleresimi!$J$2:$J$281,"E saktë",Vleresimi!$C$2:$C$281,"jo")+COUNTIFS(Vleresimi!$F$2:$F$281,5,Vleresimi!$J$2:$J$281,"Pjesërisht e saktë",Vleresimi!$C$2:$C$281,"jo"))/14 | G6: =AVERAGE(B6:F6) | H6: =STDEV(B6:F6)
A7: E pasaktë brenda bazës (42) | B7: =COUNTIFS(Vleresimi!$F$2:$F$281,1,Vleresimi!$J$2:$J$281,"E pasaktë",Vleresimi!$C$2:$C$281,"po")/42 | C7: =COUNTIFS(Vleresimi!$F$2:$F$281,2,Vleresimi!$J$2:$J$281,"E pasaktë",Vleresimi!$C$2:$C$281,"po")/42 | D7: =COUNTIFS(Vleresimi!$F$2:$F$281,3,Vleresimi!$J$2:$J$281,"E pasaktë",Vleresimi!$C$2:$C$281,"po")/42 | E7: =COUNTIFS(Vleresimi!$F$2:$F$281,4,Vleresimi!$J$2:$J$281,"E pasaktë",Vleresimi!$C$2:$C$281,"po")/42 | F7: =COUNTIFS(Vleresimi!$F$2:$F$281,5,Vleresimi!$J$2:$J$281,"E pasaktë",Vleresimi!$C$2:$C$281,"po")/42 | G7: =AVERAGE(B7:F7) | H7: =STDEV(B7:F7)
A8: Përgjigje me halucinacion (56) | B8: =COUNTIFS(Vleresimi!$F$2:$F$281,1,Vleresimi!$K$2:$K$281,"po")/56 | C8: =COUNTIFS(Vleresimi!$F$2:$F$281,2,Vleresimi!$K$2:$K$281,"po")/56 | D8: =COUNTIFS(Vleresimi!$F$2:$F$281,3,Vleresimi!$K$2:$K$281,"po")/56 | E8: =COUNTIFS(Vleresimi!$F$2:$F$281,4,Vleresimi!$K$2:$K$281,"po")/56 | F8: =COUNTIFS(Vleresimi!$F$2:$F$281,5,Vleresimi!$K$2:$K$281,"po")/56 | G8: =AVERAGE(B8:F8) | H8: =STDEV(B8:F8)
A9: Koha mesatare (s) | B9: =AVERAGEIFS(Vleresimi!$I$2:$I$281,Vleresimi!$F$2:$F$281,1) | C9: =AVERAGEIFS(Vleresimi!$I$2:$I$281,Vleresimi!$F$2:$F$281,2) | D9: =AVERAGEIFS(Vleresimi!$I$2:$I$281,Vleresimi!$F$2:$F$281,3) | E9: =AVERAGEIFS(Vleresimi!$I$2:$I$281,Vleresimi!$F$2:$F$281,4) | F9: =AVERAGEIFS(Vleresimi!$I$2:$I$281,Vleresimi!$F$2:$F$281,5) | G9: =AVERAGE(B9:F9) | H9: =STDEV(B9:F9)
A10: Saktësia e plotë – grupi A (20) | B10: =COUNTIFS(Vleresimi!$F$2:$F$281,1,Vleresimi!$J$2:$J$281,"E saktë",Vleresimi!$B$2:$B$281,"A")/20 | C10: =COUNTIFS(Vleresimi!$F$2:$F$281,2,Vleresimi!$J$2:$J$281,"E saktë",Vleresimi!$B$2:$B$281,"A")/20 | D10: =COUNTIFS(Vleresimi!$F$2:$F$281,3,Vleresimi!$J$2:$J$281,"E saktë",Vleresimi!$B$2:$B$281,"A")/20 | E10: =COUNTIFS(Vleresimi!$F$2:$F$281,4,Vleresimi!$J$2:$J$281,"E saktë",Vleresimi!$B$2:$B$281,"A")/20 | F10: =COUNTIFS(Vleresimi!$F$2:$F$281,5,Vleresimi!$J$2:$J$281,"E saktë",Vleresimi!$B$2:$B$281,"A")/20 | G10: =AVERAGE(B10:F10) | H10: =STDEV(B10:F10)
A11: Saktësia e plotë – grupi B (14) | B11: =COUNTIFS(Vleresimi!$F$2:$F$281,1,Vleresimi!$J$2:$J$281,"E saktë",Vleresimi!$B$2:$B$281,"B")/14 | C11: =COUNTIFS(Vleresimi!$F$2:$F$281,2,Vleresimi!$J$2:$J$281,"E saktë",Vleresimi!$B$2:$B$281,"B")/14 | D11: =COUNTIFS(Vleresimi!$F$2:$F$281,3,Vleresimi!$J$2:$J$281,"E saktë",Vleresimi!$B$2:$B$281,"B")/14 | E11: =COUNTIFS(Vleresimi!$F$2:$F$281,4,Vleresimi!$J$2:$J$281,"E saktë",Vleresimi!$B$2:$B$281,"B")/14 | F11: =COUNTIFS(Vleresimi!$F$2:$F$281,5,Vleresimi!$J$2:$J$281,"E saktë",Vleresimi!$B$2:$B$281,"B")/14 | G11: =AVERAGE(B11:F11) | H11: =STDEV(B11:F11)
A12: Saktësia e plotë – grupi C (9) | B12: =COUNTIFS(Vleresimi!$F$2:$F$281,1,Vleresimi!$J$2:$J$281,"E saktë",Vleresimi!$B$2:$B$281,"C")/9 | C12: =COUNTIFS(Vleresimi!$F$2:$F$281,2,Vleresimi!$J$2:$J$281,"E saktë",Vleresimi!$B$2:$B$281,"C")/9 | D12: =COUNTIFS(Vleresimi!$F$2:$F$281,3,Vleresimi!$J$2:$J$281,"E saktë",Vleresimi!$B$2:$B$281,"C")/9 | E12: =COUNTIFS(Vleresimi!$F$2:$F$281,4,Vleresimi!$J$2:$J$281,"E saktë",Vleresimi!$B$2:$B$281,"C")/9 | F12: =COUNTIFS(Vleresimi!$F$2:$F$281,5,Vleresimi!$J$2:$J$281,"E saktë",Vleresimi!$B$2:$B$281,"C")/9 | G12: =AVERAGE(B12:F12) | H12: =STDEV(B12:F12)
A13: Saktësia e plotë – grupi D (6) | B13: =COUNTIFS(Vleresimi!$F$2:$F$281,1,Vleresimi!$J$2:$J$281,"E saktë",Vleresimi!$B$2:$B$281,"D")/6 | C13: =COUNTIFS(Vleresimi!$F$2:$F$281,2,Vleresimi!$J$2:$J$281,"E saktë",Vleresimi!$B$2:$B$281,"D")/6 | D13: =COUNTIFS(Vleresimi!$F$2:$F$281,3,Vleresimi!$J$2:$J$281,"E saktë",Vleresimi!$B$2:$B$281,"D")/6 | E13: =COUNTIFS(Vleresimi!$F$2:$F$281,4,Vleresimi!$J$2:$J$281,"E saktë",Vleresimi!$B$2:$B$281,"D")/6 | F13: =COUNTIFS(Vleresimi!$F$2:$F$281,5,Vleresimi!$J$2:$J$281,"E saktë",Vleresimi!$B$2:$B$281,"D")/6 | G13: =AVERAGE(B13:F13) | H13: =STDEV(B13:F13)
A14: Saktësia e plotë – grupi E (7) | B14: =COUNTIFS(Vleresimi!$F$2:$F$281,1,Vleresimi!$J$2:$J$281,"E saktë",Vleresimi!$B$2:$B$281,"E")/7 | C14: =COUNTIFS(Vleresimi!$F$2:$F$281,2,Vleresimi!$J$2:$J$281,"E saktë",Vleresimi!$B$2:$B$281,"E")/7 | D14: =COUNTIFS(Vleresimi!$F$2:$F$281,3,Vleresimi!$J$2:$J$281,"E saktë",Vleresimi!$B$2:$B$281,"E")/7 | E14: =COUNTIFS(Vleresimi!$F$2:$F$281,4,Vleresimi!$J$2:$J$281,"E saktë",Vleresimi!$B$2:$B$281,"E")/7 | F14: =COUNTIFS(Vleresimi!$F$2:$F$281,5,Vleresimi!$J$2:$J$281,"E saktë",Vleresimi!$B$2:$B$281,"E")/7 | G14: =AVERAGE(B14:F14) | H14: =STDEV(B14:F14)
A15: Përgjigje të vlerësuara (duhet 56 për çdo ekzekutim) | B15: =COUNTIFS(Vleresimi!$F$2:$F$281,1,Vleresimi!$J$2:$J$281,"<>") | C15: =COUNTIFS(Vleresimi!$F$2:$F$281,2,Vleresimi!$J$2:$J$281,"<>") | D15: =COUNTIFS(Vleresimi!$F$2:$F$281,3,Vleresimi!$J$2:$J$281,"<>") | E15: =COUNTIFS(Vleresimi!$F$2:$F$281,4,Vleresimi!$J$2:$J$281,"<>") | F15: =COUNTIFS(Vleresimi!$F$2:$F$281,5,Vleresimi!$J$2:$J$281,"<>")
A17: Shënim: Ekzekutimi 1 = ekzekutimi origjinal; vlerësimet dhe kohët merren nga Shtojca A e tezës. Ekzekutimet 2–5 janë ekzekutimet e reja të evaluate.py me konfigurim identik (gpt-4o-mini, temperaturë 0,2, k = 5). Devijimi standard llogaritet mbi 5 ekzekutimet (STDEV).
